<?xml version="1.0" ?>
<!-- =================================================================================== -->
<!-- |    This document was autogenerated by xacro from apple_kraken.xacro             | -->
<!-- |    EDITING THIS FILE BY HAND IS NOT RECOMMENDED                                 | -->
<!-- =================================================================================== -->
<robot name="apple_kraken">
  <!-- Enable setting arguments from the launch file -->
  <link name="base_link">
    <inertial>
      <origin rpy="0.000000 -0.000000 -1.570796" xyz="1.003638 0.000000 0.000000"/>
      <!-- TODO: Update mass as volume from Meshlab will overestimate the mass -->
      <mass value="300"/>
      <inertia ixx="50.0" ixy="0.0" ixz="0.0" iyy="240.0" iyz="0.0" izz="250.0"/>
    </inertial>
    <visual>
      <origin rpy="0.000000 -0.000000 -1.570796" xyz="1.101831 0.000000 0.000000"/>
      <geometry>
        <mesh filename="meshes/VehicleBody/VehicleBody.dae" scale="1 1 1"/>
      </geometry>
    </visual>
    <collision>
      <origin rpy="1.570796 -0.000000 1.570796" xyz="0.002268 -0.000000 0.668965"/>
      <geometry>
        <box size="0.592215 0.491737 0.491032"/>
      </geometry>
    </collision>
    <collision>
      <origin rpy="-1.570796 -0.000000 -3.141593" xyz="0.963687 -0.000000 0.804149"/>
      <geometry>
        <box size="1.427517 0.762107 0.592215"/>
      </geometry>
    </collision>
    <collision>
      <origin rpy="0.000000 -0.000000 0.000000" xyz="2.197615 0.000000 0.762109"/>
      <geometry>
        <box size="0.583352 0.544691 0.264003"/>
      </geometry>
    </collision>
    <collision>
      <origin rpy="-1.570796 -0.000000 -3.141593" xyz="2.083368 0.000000 0.526601"/>
      <geometry>
        <box size="0.811846 0.207011 0.097965"/>
      </geometry>
    </collision>
    <collision>
      <origin rpy="1.570796 -0.000000 1.570796" xyz="-0.288170 -0.000000 0.522611"/>
      <geometry>
        <box size="0.592215 0.236236 0.089846"/>
      </geometry>
    </collision>
    <collision>
      <origin rpy="1.570796 -0.000000 1.570796" xyz="1.791692 -0.000000 0.907655"/>
      <geometry>
        <box size="0.592215 0.555096 0.228493"/>
      </geometry>
    </collision>
    <collision>
      <origin rpy="1.570796 -0.000000 1.570796" xyz="2.540243 0.000000 0.562592"/>
      <geometry>
        <box size="0.437199 0.131902 0.055878"/>
      </geometry>
    </collision>
  </link>
  <link name="wheel_rear_right_link">
    <inertial>
      <origin rpy="0 0 0" xyz="0 0.0 0.0"/>
      <mass value="24.5"/>
      <inertia ixx="0.787" ixy="0.0" ixz="0.0" iyy="0.787" iyz="0.0" izz="1.309"/>
    </inertial>
    <visual>
      <origin rpy="0 1.571 0" xyz="0 0 0.132"/>
      <geometry>
        <mesh filename="meshes/Wheels/WheelRight.dae" scale="0.6 0.6 0.6"/>
      </geometry>
    </visual>
    <collision>
      <origin rpy="0 0 0" xyz="0 0 0.066"/>
      <geometry>
        <cylinder length="0.132" radius="0.3"/>
      </geometry>
    </collision>
  </link>
  <link name="wheel_rear_left_link">
    <inertial>
      <origin rpy="0 0 0" xyz="0 0.0 0.132"/>
      <mass value="24.5"/>
      <inertia ixx="0.787" ixy="0.0" ixz="0.0" iyy="0.787" iyz="0.0" izz="1.309"/>
    </inertial>
    <visual>
      <origin rpy="0 -1.571 0 " xyz="0 0 0.0"/>
      <geometry>
        <mesh filename="meshes/Wheels/WheelLeft.dae" scale="0.6 0.6 0.6"/>
      </geometry>
    </visual>
    <collision>
      <origin rpy="0 0 0" xyz="0 0 -0.066"/>
      <geometry>
        <cylinder length="0.132" radius="0.3"/>
      </geometry>
    </collision>
  </link>
  <link name="wheel_front_right_link">
    <inertial>
      <origin rpy="0 0 0" xyz="0 0.0 -0.066"/>
      <mass value="24.5"/>
      <inertia ixx="0.787" ixy="0.0" ixz="0.0" iyy="0.787" iyz="0.0" izz="1.309"/>
    </inertial>
    <visual>
      <origin rpy="0 1.571 0" xyz="0 0 0"/>
      <geometry>
        <mesh filename="meshes/Wheels/WheelRight.dae" scale="0.6 0.6 0.6"/>
      </geometry>
    </visual>
    <collision>
      <origin rpy="0 0 0" xyz="0 0 -0.066"/>
      <geometry>
        <cylinder length="0.132" radius="0.3"/>
      </geometry>
    </collision>
  </link>
  <link name="wheel_front_left_link">
    <inertial>
      <origin rpy="0 0 0" xyz="0 0.0 0.066"/>
      <mass value="24.5"/>
      <inertia ixx="0.787" ixy="0.0" ixz="0.0" iyy="0.787" iyz="0.0" izz="1.309"/>
    </inertial>
    <visual>
      <origin rpy="0 -1.571 0" xyz="0 0 0.132"/>
      <geometry>
        <mesh filename="meshes/Wheels/WheelLeft.dae" scale="0.6 0.6 0.6"/>
      </geometry>
    </visual>
    <collision>
      <origin rpy="0 0 0" xyz="0 0 0.066"/>
      <geometry>
        <cylinder length="0.132" radius="0.3"/>
      </geometry>
    </collision>
  </link>
  <link name="steering_front_right_link">
    <inertial>
      <origin rpy="0 0 -1.571" xyz="0 0 -0.04"/>
      <mass value="1"/>
      <inertia ixx="1" ixy="0.0" ixz="0.0" iyy="1" iyz="0.0" izz="1"/>
    </inertial>
    <visual>
      <origin rpy="0 0 -1.571" xyz="0 -0.03 -0.03"/>
      <geometry>
        <mesh filename="meshes/Steering/SteeringArmRight.dae" scale="0.6 0.6 0.6"/>
      </geometry>
    </visual>
  </link>
  <link name="steering_front_left_link">
    <inertial>
      <origin rpy="0 0 -1.571" xyz="0 0 -0.04"/>
      <mass value="1"/>
      <inertia ixx="1" ixy="0.0" ixz="0.0" iyy="1" iyz="0.0" izz="1"/>
    </inertial>
    <visual>
      <origin rpy="0 0 -1.571" xyz="0 0.03 -0.03"/>
      <geometry>
        <mesh filename="meshes/Steering/SteeringArmLeft.dae" scale="0.6 0.6 0.6"/>
      </geometry>
    </visual>
  </link>
  <joint name="wheel_rear_right_joint" type="continuous">
    <origin rpy="-1.570796 -0.000000 0.000000" xyz="0.000000 0.35 0.3"/>
    <parent link="base_link"/>
    <child link="wheel_rear_right_link"/>
    <axis xyz="0.0 0.0 1.0"/>
    <limit effort="1000000.0" velocity="1000.0"/>
  </joint>
  <joint name="wheel_rear_left_joint" type="continuous">
    <origin rpy="-1.570796 -0.000000 0.000000" xyz="0.000000 -0.35 0.3"/>
    <parent link="base_link"/>
    <child link="wheel_rear_left_link"/>
    <axis xyz="0.0 0.0 1.0"/>
    <limit effort="1000000.0" velocity="1000.0"/>
  </joint>
  <joint name="wheel_front_right_joint" type="continuous">
    <origin rpy="-1.571 0 0" xyz="0 -0.12499999999999997 0"/>
    <parent link="steering_front_right_link"/>
    <child link="wheel_front_right_link"/>
    <axis xyz="0.0 0.0 1.0"/>
    <limit effort="1000000.0" velocity="1000.0"/>
  </joint>
  <joint name="wheel_front_left_joint" type="continuous">
    <origin rpy="-1.571 0 0" xyz="0 0.12499999999999997 0"/>
    <parent link="steering_front_left_link"/>
    <child link="wheel_front_left_link"/>
    <axis xyz="0.0 0.0 1.0"/>
    <limit effort="1000000.0" velocity="1000.0"/>
  </joint>
  <joint name="steering_front_right_joint" type="revolute">
    <origin rpy="0 0 0" xyz="2.2 -0.225 0.3"/>
    <parent link="base_link"/>
    <child link="steering_front_right_link"/>
    <axis xyz="0.0 0.0 1.0"/>
    <dynamics damping="2.0" friction="1.0"/>
    <limit effort="1000000.0" lower="-0.5235" upper="0.5235" velocity="100"/>
  </joint>
  <joint name="steering_front_left_joint" type="revolute">
    <origin rpy="0 0 0" xyz="2.2 0.225 0.3"/>
    <parent link="base_link"/>
    <child link="steering_front_left_link"/>
    <axis xyz="0.0 0.0 1.0"/>
    <dynamics damping="2.0" friction="1.0"/>
    <limit effort="1000000.0" lower="-0.5235" upper="0.5235" velocity="100"/>
  </joint>
  <!--     
    <link name="manipulator_link_0_old">
      <inertial>
        <origin rpy="0.1745 0 0" xyz="0.0 -0.6 2.0"/>
        <mass value="25.0"/>
        <inertia ixx="0.002" ixy="0.0" ixz="0.0" iyy="0.068" iyz="0.0" izz="0.067"/>
      </inertial>

      <visual>
        <origin rpy="-0.174533 0 0" xyz="0.9 -0.65 2.4"/>
        <geometry>
          <box size = "0.1 0.1 2.0"/>
        </geometry>
      </visual>
      <visual>
        <origin rpy="-0.174533 0 0" xyz="-0.9 -0.65 2.4"/>
        <geometry>
          <box size = "0.1 0.1 2.0"/>
        </geometry>
      </visual>

      <collision>
        <origin rpy="-0.174533 0 0" xyz="0.9 -0.65 2.4"/>
        <geometry>
          <box size = "0.1 0.1 2.0"/>
        </geometry>
      </collision>
        <collision>
        <origin rpy="-0.174533 0 0" xyz="-0.9 -0.65 2.4"/>
        <geometry>
          <box size = "0.1 0.1 2.0"/>
        </geometry>
      </collision>
    </link>
    <joint name="manipulator_joint_0" type="fixed">
      <origin rpy="0 0 0" xyz="${manip_x+0.003927} ${manip_y} ${manip_z-1.0}"/>
      <parent link="base_link"/>
      <child link="manipulator_link_0_old"/>
    </joint>  -->
  <link name="kraken_manipulator_link_0">
    <inertial>
      <origin rpy="0.1745 0 0" xyz="0.0 -0.6 2.0"/>
      <mass value="25.0"/>
      <inertia ixx="0.002" ixy="0.0" ixz="0.0" iyy="0.068" iyz="0.0" izz="0.067"/>
    </inertial>
    <visual>
      <origin rpy="0 0 -1.571" xyz="0.0 0.0 0"/>
      <geometry>
        <mesh filename="meshes/ChassisAndFrame/ChassisAndFrame.dae" scale="1 1 1"/>
      </geometry>
    </visual>
    <collision>
      <origin rpy="1.570798 1.396264 4.712389" xyz="0.485927 -0.460373 1.404769"/>
      <geometry>
        <box size="2.451889 0.088234 0.088234"/>
      </geometry>
    </collision>
    <collision>
      <origin rpy="1.570798 1.396264 4.712389" xyz="-1.774321 -0.460373 1.404769"/>
      <geometry>
        <box size="2.451889 0.088234 0.088234"/>
      </geometry>
    </collision>
    <collision>
      <origin rpy="-0.174561 0.000000 0.000000" xyz="-0.646611 -0.254306 2.573430"/>
      <geometry>
        <box size="2.087586 0.088237 0.062286"/>
      </geometry>
    </collision>
  </link>
  <link name="kraken_manipulator_link_1">
    <inertial>
      <origin rpy="0 0 0" xyz="0.0 0.0 0.0"/>
      <mass value="25.0"/>
      <inertia ixx="0.002" ixy="0.0" ixz="0.0" iyy="0.068" iyz="0.0" izz="0.067"/>
    </inertial>
    <visual>
      <origin rpy="0 0 -1.571" xyz="0.0 0.0 0"/>
      <geometry>
        <mesh filename="meshes/VacuumMechanismPart01/VacuumMechanismPart01.dae" scale="1 1 1"/>
      </geometry>
    </visual>
    <collision>
      <origin rpy="-0.001888 -0.000000 0.000000" xyz="0.000000 0.062564 -0.000045"/>
      <geometry>
        <box size="2.019587 0.172379 0.067739"/>
      </geometry>
    </collision>
  </link>
  <link name="kraken_manipulator_link_2">
    <inertial>
      <origin rpy="0 0 0" xyz="0.0 0.0 0.0"/>
      <mass value="10.0"/>
      <inertia ixx="0.05" ixy="0.0" ixz="0.0" iyy="0.05" iyz="0.0" izz="0.05"/>
    </inertial>
    <visual>
      <origin rpy="1.571 0 -1.571" xyz="0.0 0.0 0"/>
      <geometry>
        <mesh filename="meshes/VacuumMechanismPart02/VacuumMechanismPart02.dae" scale="1 1 1"/>
      </geometry>
    </visual>
    <collision>
      <origin rpy="0.0 0.0 0.0" xyz="0.0 0.0 0.0"/>
      <geometry>
        <box size="0.396177 0.322944 0.312368"/>
      </geometry>
    </collision>
    <collision>
      <origin rpy="-1.570829 0 0 " xyz="-0.066974 -0.2 -0.000000"/>
      <geometry>
        <cylinder length="0.3" radius="0.06"/>
      </geometry>
    </collision>
  </link>
  <!-- Nozzle -->
  <link name="kraken_manipulator_link_3">
    <inertial>
      <origin rpy="0 0 0" xyz="0.0 0.0 0.0"/>
      <mass value="5.0"/>
      <inertia ixx="0.01" ixy="0.0" ixz="0.0" iyy="0.01" iyz="0.0" izz="0.01"/>
    </inertial>
    <visual>
      <origin rpy="0 -1.571 0" xyz="0.0 0.0 0"/>
      <geometry>
        <mesh filename="meshes/VacuumNozzle/VacuumNozzle.dae" scale="1 1 1"/>
      </geometry>
    </visual>
    <collision>
      <origin rpy="0 0 0" xyz="0 0 0.0"/>
      <geometry>
        <cylinder length="0.25" radius="0.08"/>
      </geometry>
    </collision>
    <collision>
      <origin rpy="0 0 0" xyz="0 0 0.45"/>
      <geometry>
        <sphere radius="0.03"/>
      </geometry>
    </collision>
  </link>
  <!-- Nozzle02 -->
  <link name="kraken_manipulator_link_4">
    <inertial>
      <origin rpy="0 0 0" xyz="0.0 0.0 0.0"/>
      <mass value="5.0"/>
      <inertia ixx="0.01" ixy="0.0" ixz="0.0" iyy="0.01" iyz="0.0" izz="0.01"/>
    </inertial>
    <visual>
      <origin rpy="0 -1.571 0" xyz="0.0 0.0 0"/>
      <geometry>
        <mesh filename="meshes/VacuumNozzle02/VacuumNozzle02.dae" scale="1 1 1"/>
      </geometry>
    </visual>
    <collision>
      <origin rpy="0 0 0" xyz="0 0 0.19"/>
      <geometry>
        <cylinder length="0.38" radius="0.06"/>
      </geometry>
    </collision>
  </link>
  <joint name="kraken_manipulator_joint_0" type="fixed">
    <origin rpy="0 0 0" xyz="1.1 0 0"/>
    <parent link="base_link"/>
    <child link="kraken_manipulator_link_0"/>
  </joint>
  <!-- Joint that moves manipulator along Z-Axis -->
  <joint name="kraken_manipulator_joint_1" type="prismatic">
    <origin rpy="-0.1745 0 0" xyz="0.44999900000000004 -0.511055 1.6569"/>
    <parent link="base_link"/>
    <child link="kraken_manipulator_link_1"/>
    <axis xyz="0.0 0.0 1.0"/>
    <dynamics damping="2.0" friction="1.0"/>
    <limit effort="1000.0" lower="-1.2" upper="0.67" velocity="1.0"/>
  </joint>
  <!-- Joint that moves manipulator along X-Axis -->
  <joint name="kraken_manipulator_joint_2" type="prismatic">
    <origin rpy="0 1.571 0" xyz="0 0 0"/>
    <parent link="kraken_manipulator_link_1"/>
    <child link="kraken_manipulator_link_2"/>
    <axis xyz="0.0 0.0 1.0"/>
    <dynamics damping="2.0" friction="1.0"/>
    <limit effort="1000.0" lower="-1.0" upper="1.0" velocity="1.0"/>
  </joint>
  <!-- Nozzle -->
  <joint name="kraken_manipulator_joint_3" type="prismatic">
    <origin rpy="1.571 0 0" xyz="-0.067 -0.35 -0.004"/>
    <parent link="kraken_manipulator_link_2"/>
    <child link="kraken_manipulator_link_3"/>
    <axis xyz="0.0 0.0 1.0"/>
    <dynamics damping="2.0" friction="1.0"/>
    <limit effort="1000.0" lower="0" upper="0.28" velocity="1.0"/>
  </joint>
  <!-- Nozzle02 -->
  <joint name="kraken_manipulator_joint_4" type="prismatic">
    <origin rpy="0 0 0" xyz="0 0 0"/>
    <parent link="kraken_manipulator_link_3"/>
    <child link="kraken_manipulator_link_4"/>
    <axis xyz="0.0 0.0 1.0"/>
    <dynamics damping="2.0" friction="1.0"/>
    <limit effort="1000.0" lower="0" upper="0.28" velocity="1.0"/>
  </joint>
</robot>
